Workbook

Sheet coding
A1: participant_id | B1: stance_text | C1: stance_suggested | D1: coder_1_stance | E1: coder_2_stance | F1: stance_agreed | G1: barrier_text | H1: barriers_suggested | I1: coder_1_themes | J1: coder_2_themes | K1: barriers_agreed | L1: note | M1: llm_stance | N1: llm_stance_vs_sug | O1: llm_themes | P1: llm_themes_vs_sug | Q1: llm_confidence | R1: llm_note
A2: P001 | B2: الاعتمادية | C2: dependency | D2: dependency | E2: dependency | G2: عدم دقة الاجابة || تذبذب المعلومات | H2: T1 | M2: dependency | N2: =IF($M2="","",IF($M2=$C2,"match","OVERRIDE")) -> match | O2: T1 | P2: =IF($O2="","",IF($O2=$H2,"match","OVERRIDE")) -> match | Q2: high
A3: P002 | B3: يؤدي إلى الاعتمادية | C3: dependency | D3: conditional | E3: innovation | G3: الدقة || شح المصادر والمراجع | H3: T1,T4 | M3: dependency | N3: =IF($M3="","",IF($M3=$C3,"match","OVERRIDE")) -> match | O3: T1,T4 | P3: =IF($O3="","",IF($O3=$H3,"match","OVERRIDE")) -> match | Q3: high
A4: P003 | B4: يؤدي إلى الاعتمادية | C4: dependency | D4: uncodable | E4: uncodable | G4: محايد || لا شيء | H4: T9 | M4: dependency | N4: =IF($M4="","",IF($M4=$C4,"match","OVERRIDE")) -> match | O4: T9 | P4: =IF($O4="","",IF($O4=$H4,"match","OVERRIDE")) -> match | Q4: high
A5: P004 | B5: إذا زاد استخدامه عن حده فيؤدي للاعتمادية | C5: conditional | D5: dependency | E5: innovation | F5: dependency | G5: عدم توفر مصادر موثوقة || عدم الفهم السريع،و قلة الدقة في المعاني | H5: T1,T4 | M5: conditional | N5: =IF($M5="","",IF($M5=$C5,"match","OVERRIDE")) -> match | O5: T1,T4 | P5: =IF($O5="","",IF($O5=$H5,"match","OVERRIDE")) -> match | Q5: high
A6: P005 | B6: يهدم الابتكار والفردية | D6: innovation | E6: conditional | F6: conditional | G6: لا يمكن الاعتماد عليه في الدراسة، يمكن استخدامه فقط للبحث عن معلومات سطحية، ولا يصلح لشيء أعمق من ذلك || لا يستطيع الذكاء الاصطناعي التعامل مع اللغة العربية الا في ابسط الحالات | H6: T1,T2 | L6: no suggestion available - please code from the text | M6: dependency | N6: =IF($M6="","",IF($M6=$C6,"match","OVERRIDE")) -> OVERRIDE | O6: T1,T2 | P6: =IF($O6="","",IF($O6=$H6,"match","OVERRIDE")) -> match | Q6: high | R6: Suggestion blank. 'يهدم الابتكار والفردية' = destroys innovation and individuality. The keyword الابتكار is present but negated by يهدم; predicate governs, so dependency.
A7: P006 | B7: يعزز الابتكار الفردي | C7: innovation | D7: conditional | G7: صعوبة فهمه للغة || لا يفهم قواعد اللغة العربية كثيرًا | H7: T2 | M7: innovation | N7: =IF($M7="","",IF($M7=$C7,"match","OVERRIDE")) -> match | O7: T2 | P7: =IF($O7="","",IF($O7=$H7,"match","OVERRIDE")) -> match | Q7: high
A8: P007 | B8: في بعض الأحيان | C8: uncodable | G8: المعلومات الخاطئة || تحليله للأبيات بصورة خاطئه او اعطائي أشياء من تأليفه | H8: T1,T3 | M8: uncodable | N8: =IF($M8="","",IF($M8=$C8,"match","OVERRIDE")) -> match | O8: T1,T3 | P8: =IF($O8="","",IF($O8=$H8,"match","OVERRIDE")) -> match | Q8: high
A9: P008 | B9: ! | C9: uncodable | G9: لا يفهم كثيرا ف اللغة || ! | H9: T1 | M9: uncodable | N9: =IF($M9="","",IF($M9=$C9,"match","OVERRIDE")) -> match | O9: T2 | P9: =IF($O9="","",IF($O9=$H9,"match","OVERRIDE")) -> OVERRIDE | Q9: high | R9: 'لا يفهم كثيرا ف اللغة' names language comprehension, not generic inaccuracy. Suggestion T1.
A10: P009 | B10: كلاهما | C10: conditional | G10: التدقيق اللغوي والاملائي || دقة المراجع | H10: T1,T4 | M10: conditional | N10: =IF($M10="","",IF($M10=$C10,"match","OVERRIDE")) -> match | O10: T2,T4 | P10: =IF($O10="","",IF($O10=$H10,"match","OVERRIDE")) -> OVERRIDE | Q10: med | R10: 'التدقيق اللغوي والاملائي' - orthography/proofreading is an Arabic linguistic domain (T2), not generic inaccuracy. Depends on whether إملاء is admitted to T2 (see rule R-T2b).
A11: P010 | B11: يعزز الابتكار و الفردية | C11: innovation | G11: الدكاترةلا يعجبهم ذلك || الخطأ في تحديد نسبة البيت للشاعر | H11: T3,T7 | M11: innovation | N11: =IF($M11="","",IF($M11=$C11,"match","OVERRIDE")) -> match | O11: T3,T7 | P11: =IF($O11="","",IF($O11=$H11,"match","OVERRIDE")) -> match | Q11: high
A12: P011 | B12: يعزز الابتكار | C12: innovation | G12: لا يوجد || عدم وجود تطبيقات تدعم اللغه العربية | H12: T6 | M12: innovation | N12: =IF($M12="","",IF($M12=$C12,"match","OVERRIDE")) -> match | O12: T6 | P12: =IF($O12="","",IF($O12=$H12,"match","OVERRIDE")) -> match | Q12: high
A13: P012 | B13: ممكن الاثنين | C13: conditional | G13: لا يفهم النحو || لا يعرف كما قلت سابقا في قواعد النحو | H13: T2 | M13: conditional | N13: =IF($M13="","",IF($M13=$C13,"match","OVERRIDE")) -> match | O13: T2 | P13: =IF($O13="","",IF($O13=$H13,"match","OVERRIDE")) -> match | Q13: high
A14: P013 | B14: ارى تنه يعزز الابتكار إلى جانب انه يمكن ان يكون داعم لطالب من جوانب مختلفه | C14: innovation | G14: ضعف الدقه العلميه || .. | H14: T1 | M14: innovation | N14: =IF($M14="","",IF($M14=$C14,"match","OVERRIDE")) -> match | O14: T1 | P14: =IF($O14="","",IF($O14=$H14,"match","OVERRIDE")) -> match | Q14: high
A15: P014 | B15: الآثنين معاً | C15: conditional | G15: قلة المعرفه به و المعلومات المغلوطه || التحليل الغير دقيق مثلا | H15: T1 | M15: conditional | N15: =IF($M15="","",IF($M15=$C15,"match","OVERRIDE")) -> match | O15: T1,T5 | P15: =IF($O15="","",IF($O15=$H15,"match","OVERRIDE")) -> OVERRIDE | Q15: high | R15: 'قلة المعرفه به' = the student's own limited knowledge of the tool -> T5, missed by suggestion.
A16: P015 | B16: محايد ، بعض الناس يعتمدون عليه بشكل مفرط بينما آخرون يعتمدون عليه كوسيلة للإبداع والابتكار | C16: conditional | G16: عدم استجابة الذكاء الاصطناعي في كل نقطة الإجابات الخاطئة معلومات مغلوطة بدون توثيق || يحلل بشكل خاطئ ، لا يجيد الاعراب ويخطأ كثيرًا فيه | H16: T1,T2,T4 | M16: conditional | N16: =IF($M16="","",IF($M16=$C16,"match","OVERRIDE")) -> match | O16: T1,T2,T4 | P16: =IF($O16="","",IF($O16=$H16,"match","OVERRIDE")) -> match | Q16: high
A17: P016 | B17: على حسب طريقة استخدامه | C17: conditional | G17: عدم دقة نتائج الذكاء الاصطناعي في الادب العربي || عدم دقة البيانات وعدم صحة التحليلات صعوبة العمل على ملفات كبيرة | H17: T1 | M17: conditional | N17: =IF($M17="","",IF($M17=$C17,"match","OVERRIDE")) -> match | O17: T1,T8 | P17: =IF($O17="","",IF($O17=$H17,"match","OVERRIDE")) -> OVERRIDE | Q17: low | R17: 'صعوبة العمل على ملفات كبيرة' = difficulty with large files -> a usage limit (T8) rather than an accuracy problem. Only holds if T8 is widened per rule R-T8.
A18: P017 | B18: يعزز الابتكار والفردية | C18: innovation | G18: تعليق البرنامج المستخدم وتكراره للذي يقول || عدم فهم قواعد اللغة بشكل جيد خاصة لو خدعته بأكثر من قاعدة بسؤال | H18: T2 | M18: innovation | N18: =IF($M18="","",IF($M18=$C18,"match","OVERRIDE")) -> match | O18: T2,T8 | P18: =IF($O18="","",IF($O18=$H18,"match","OVERRIDE")) -> OVERRIDE | Q18: low | R18: 'تعليق البرنامج وتكراره' = the app hanging and repeating -> technical availability (T8) under R-T8.
A19: P018 | B19: يعزّز الابتكار إذا استُخدم بوعي، وقد يسبب الاعتمادية إذا أُسيء استخدامه | C19: conditional | G19: عدم دقة بعض النتائج، وصعوبة التحقق من المصادر || أحيانًا يعطي معلومات غير دقيقة أو عامة، مما يسبب التباسًا في الفهم | H19: T1,T4 | M19: conditional | N19: =IF($M19="","",IF($M19=$C19,"match","OVERRIDE")) -> match | O19: T1,T4 | P19: =IF($O19="","",IF($O19=$H19,"match","OVERRIDE")) -> match | Q19: high
A20: P019 | B20: يعتمد على طريقة الاستخدام | C20: conditional | G20: عدم دقة المعلومات اللتي يقدمها و ضعف الفهم للسياق احيانا || لا توجد | H20: T1 | M20: conditional | N20: =IF($M20="","",IF($M20=$C20,"match","OVERRIDE")) -> match | O20: T1 | P20: =IF($O20="","",IF($O20=$H20,"match","OVERRIDE")) -> match | Q20: high
A21: P020 | B21: ارى أنه يعزز الإبتكار | C21: innovation | G21: لا يمكن الاعتماد عليه لأنه يعطي إجابات غير دقيقة || عندما ارغب ان يشرح لي سؤال في النحو يجمع بين قاعدتين لا يستطيع حله بشكل صحيح | H21: T1,T2 | M21: innovation | N21: =IF($M21="","",IF($M21=$C21,"match","OVERRIDE")) -> match | O21: T1,T2 | P21: =IF($O21="","",IF($O21=$H21,"match","OVERRIDE")) -> match | Q21: high
A22: P021 | B22: قد يؤدي إلى الاعتمادية إذا أُسيء استخدامه، لكنه في المقابل يعزز الابتكار إذا استُخدم كأداة مساعدة تدعم الفهم وتوليد الأفكار، لذلك تأثيره يتوقف على طريقة استخدامه. | C22: conditional | G22: عدم دقة بعض المعلومات مما يجعلني بحاجة إلى التحقق منها من مصادر موثوقة كذلك أحيانا قد يقدم الذكاء الاصطناعي إجابات عامة أو غير تفصيلية بالشكل الذي يناسب المستوى الأكاديمي المطلوب. || عدم دقة الإجابات. | H22: T1 | M22: conditional | N22: =IF($M22="","",IF($M22=$C22,"match","OVERRIDE")) -> match | O22: T1 | P22: =IF($O22="","",IF($O22=$H22,"match","OVERRIDE")) -> match | Q22: high
A23: P022 | B23: هذا يعتمد على استخدام الشخص، فمنهم من يتخذه مساعدًا ومرشدًا ولا يصدّق في كلّ شيء يطرحه، بل يتأكد ويبحث. ومنهم من يعتمد عليه اعتمادًا كليًا. وفي الحالة الأولى يعزز الابتكار لما يطرحه من خيوط أفكار دقيقة قد يطورها العقل البشري المتلقي لها، وفي الحالة الثانية تكمن الاعتمادية. | C23: conditional | G23: عدم دقة المصادر التي يعتمد عليها، فهو كثيرًا ما يحيل إلى كتب لغير مؤلفيها، وأحيانًا يأتي بالمعلومة ويوثقها من مرجع لا علاقة له بها أصلًا. كما أنّ لغته لا تعد لغة رصينة، بيْد أنّنا لا نستطيع الحكم عليها بالخطأ. || ينسب الذكاء الاصطناعي أبيات الشعر لغير قائلها، بل ويخترع لشاعر ما أبيات لم يقلها. ليس دقيقا في التفريق بين الصيغ الصرفية. يخطأ كثيرًا في الإعراب | H23: T1,T2,T3,T4 | M23: conditional | N23: =IF($M23="","",IF($M23=$C23,"match","OVERRIDE")) -> match | O23: T1,T2,T3,T4 | P23: =IF($O23="","",IF($O23=$H23,"match","OVERRIDE")) -> match | Q23: high
A24: P023 | B24: قد يؤدي إلى الاثنين معا حسب استخدام الشخص وخبرته وقدرته على نقد المحتوى وكتابة أوامر قوية وقدرته على التحقق من صدق الإجابة والمراجع التي استشهد بها | C24: conditional | G24: قلة الخبرة والقدرة على نقد المحتوى المقدم من برامج الذكاء الاصطناعي التوليدية || ضعف القدرة على نقد المحتوى المقدم، كذلك دقة الإجابات المقدمة لأن معظمها تتعامل مع اللغة الإنجليزية | H24: T1,T5,T6 | M24: conditional | N24: =IF($M24="","",IF($M24=$C24,"match","OVERRIDE")) -> match | O24: T1,T5,T6 | P24: =IF($O24="","",IF($O24=$H24,"match","OVERRIDE")) -> match | Q24: high
A25: P024 | B25: قد يؤدي إلى الاعتمادية في حال عدم التدقيق خلفه وعدم التأكد، ولكن قد يعزز روح النقد لديك في حال تتبعت المعلومة وتأكدت من صحتها خلفه. | C25: conditional | G25: دقة المعلومات، وموثوقيتها || بعض المعلومات التي يأتي بها خاطئة، أو لادخل لها بالموضوع الذي أبحث عنه. | H25: T1 | M25: conditional | N25: =IF($M25="","",IF($M25=$C25,"match","OVERRIDE")) -> match | O25: T1 | P25: =IF($O25="","",IF($O25=$H25,"match","OVERRIDE")) -> match | Q25: high
A26: P025 | B26: كلاهما | C26: conditional | G26: عدم الدقة في المعلومات-كثرة الأخطاء || معلومة خاطئة | H26: T1 | M26: conditional | N26: =IF($M26="","",IF($M26=$C26,"match","OVERRIDE")) -> match | O26: T1 | P26: =IF($O26="","",IF($O26=$H26,"match","OVERRIDE")) -> match | Q26: high
A27: P026 | B27: على حسب استخدام الفرد. غالبًا يؤدي إلى الاعتمادية خاصة إذا بالغ الشخص في استخدامه، لكن لو استخدمه بصورة مناسبة وبطريقة ذكية يستطيع الاستفادة منه لكسب الخبرات وتحسين الابتكار والإبداع. | C27: conditional | G27: ١. غالبًا الذكاء الاصطناعي غير دقيق في اللغة العربية ويقدّم أحيانًا معلومات خاطئة. ٢. رفض الدكاترة قيام الطلبة باستخدام الذكاء الاصطناعي حتى لو على سبيل المساعدة وتقديم أفكار مثلًا. || ١. لا يدعم اللغة العربية في توليد الصور، غالبًا يكتب الحروف والكلمات بصورة غير واضحة أو عشوائية. ٢. لا يمكن الاستفادة منه في النحو بصورة كبيرة. | H27: T1,T2,T6,T7 | M27: conditional | N27: =IF($M27="","",IF($M27=$C27,"match","OVERRIDE")) -> match | O27: T1,T2,T6,T7 | P27: =IF($O27="","",IF($O27=$H27,"match","OVERRIDE")) -> match | Q27: high
A28: P027 | B28: يؤدي إلى الاعتمادية بشكل أكبر . | C28: dependency | G28: عدم دقة المعلومات والمصادر. || عدم دقة الشرح ومعلومات غير صحيحة . | H28: T1,T4 | M28: dependency | N28: =IF($M28="","",IF($M28=$C28,"match","OVERRIDE")) -> match | O28: T1,T4 | P28: =IF($O28="","",IF($O28=$H28,"match","OVERRIDE")) -> match | Q28: high
A29: P028 | B29: قد يعزز الابتكار والفردية إذا تم استخدامه بطريقة صحيحة ، لأنه يساعد على تطوير الأفكار ولكن الاعتماد الكلي عليه قد يضعف الإبداع الشخصي. | C29: conditional | G29: عدم دقة بعض المعلومات أحيانًا، وصعوبة التأكد من موثوقية المصادر بسبب انه قد يقدم مصادر غير موجودة من الأساس. || التجارب السلبية التي واجهتها أن بعض الإجابات كانت غير دقيقة أو تحتوي على معلومات غير موثوقة، مما اضطرني إلى مراجعة المصادر والتأكد من صحة المعلومات قبل الاعتماد عليها ، ايضاً ان الذكاء الاصطناعي لا يدعم العربية كثيرًا على عكس اللغة الإنجليزية. | H29: T1,T4,T6 | M29: conditional | N29: =IF($M29="","",IF($M29=$C29,"match","OVERRIDE")) -> match | O29: T1,T4,T6 | P29: =IF($O29="","",IF($O29=$H29,"match","OVERRIDE")) -> match | Q29: high
A30: P029 | B30: قد يعزز الابتكار والفرديه على المدى الطويل | C30: innovation | G30: عدم وجود اداه تجلب معلومات دقيقه عن اللغه العربيه || توليد اعرابات خاطئه وغير منطقيه اصلا | H30: T1,T2 | M30: innovation | N30: =IF($M30="","",IF($M30=$C30,"match","OVERRIDE")) -> match | O30: T1,T2,T6 | P30: =IF($O30="","",IF($O30=$H30,"match","OVERRIDE")) -> OVERRIDE | Q30: med | R30: Hedged ('قد يعزز... على المدى الطويل') but no usage condition - innovation, not conditional. | 'عدم وجود اداه تجلب معلومات دقيقه عن اللغه العربيه' = absence of an Arabic tool -> T6, missed.
A31: P030 | B31: يعزز الإبتكار | C31: innovation | G31: . || . | M31: innovation | N31: =IF($M31="","",IF($M31=$C31,"match","OVERRIDE")) -> match | O31: T9 | P31: =IF($O31="","",IF($O31=$H31,"match","OVERRIDE")) -> OVERRIDE | Q31: high | R31: Suggestion blank. Both parts are '.' - no barrier stated.
A32: P031 | B32: أرى أنه يعتمد على الشخص، بالنسبة لي لا أعتمد عليه اعتمادا كليا إنما يساعدني في الابتكار خاصة في العروض التقديمية | C32: conditional | G32: الإجابات غير الدقيقة || عندما أطلب منه أن يلخص لي قصة أو موضوع أحياناً تلخيصه يكون مخل بالمعنى بالإضافة إلى الإجابات غير الدقيقة أحيانا | H32: T1 | M32: conditional | N32: =IF($M32="","",IF($M32=$C32,"match","OVERRIDE")) -> match | O32: T1 | P32: =IF($O32="","",IF($O32=$H32,"match","OVERRIDE")) -> match | Q32: high
A33: P032 | B33: الابتكار | C33: innovation | G33: لا يتعرف على قواعد العربية || لا يتعمق في الاجابة | H33: T1,T2 | M33: innovation | N33: =IF($M33="","",IF($M33=$C33,"match","OVERRIDE")) -> match | O33: T1,T2 | P33: =IF($O33="","",IF($O33=$H33,"match","OVERRIDE")) -> match | Q33: high
A34: P033 | B34: الإثنان معًا، يجب أن يكون الاستخدام واعٍ | C34: conditional | G34: عدم الدقة || لا يجيد كل الجوانب في اللغة، ربما يستطيع الإعراب بشكل جيد. | H34: T1,T2 | M34: conditional | N34: =IF($M34="","",IF($M34=$C34,"match","OVERRIDE")) -> match | O34: T1,T2 | P34: =IF($O34="","",IF($O34=$H34,"match","OVERRIDE")) -> match | Q34: high
A35: P034 | B35: هذا الأمر نسبي و يعتمد على عقلية من يستخدمه | C35: conditional | G35: أنه لا يفقه اللغة العربية بالشكل الذي أتطلع له || طلبت منه مساعدتي في حل واجب منزلي و لم أحصل في هذا الواجب على درجة كاملة مثلما توقعت (اعتمدت على الذكاء الاصطناعي بنسبة ٩٨% تقريبا) و هذا عزز نبوءة دكتور المقرر أن الذكاء الاصطناعي لن يفيدنا في حل ذلك الواجب، و قد كنت أحاول إثبات العكس... | H35: T1,T2 | M35: conditional | N35: =IF($M35="","",IF($M35=$C35,"match","OVERRIDE")) -> match | O35: T1,T2 | P35: =IF($O35="","",IF($O35=$H35,"match","OVERRIDE")) -> match | Q35: med | R35: Mentions the professor's prediction being confirmed, but that is not institutional resistance, so no T7.
A36: P035 | B36: حسب نوع الاستخدام الفردي اذا كان نسخاً شاملاً فهو يؤدي إلى الاعتمادية وتقليل الابتكار والفردية. | C36: conditional | G36: عدم المقدرة على كتابة أوامر prompts لجعل النتائج دقيقة في الأدب واللغة العربية أكثر دقة || عدم دقة البيانات والمعلومات | H36: T1,T5 | M36: conditional | N36: =IF($M36="","",IF($M36=$C36,"match","OVERRIDE")) -> match | O36: T1,T5 | P36: =IF($O36="","",IF($O36=$H36,"match","OVERRIDE")) -> match | Q36: high
A37: P036 | B37: يعتمد على استخدام الفرد له | C37: conditional | G37: منحي إجابات خاطئة وغير دقيقة ، بعض الإجابات تأتي من مصادر غير. موثوقة ، طول مدة توليد الصور والمقاطع || يمنحني إجابات من وحي خياله لا أساس لها من الصحة و أيضا تأخره في منح الإجابات | H37: T1,T8 | M37: conditional | N37: =IF($M37="","",IF($M37=$C37,"match","OVERRIDE")) -> match | O37: T1,T4,T8 | P37: =IF($O37="","",IF($O37=$H37,"match","OVERRIDE")) -> OVERRIDE | Q37: med | R37: 'بعض الإجابات تأتي من مصادر غير موثوقة' -> T4, missed by suggestion.
A38: P037 | B38: الاعتمادية | C38: dependency | G38: الذكاء الاصطناعي يجيب بطريقة خاطئة وعند تحليل الجداول والاحصائيات يحذف بعض النقاط كأن مسح الصورة لم يتم بطريقة صحيحة فتصبح المعلومات ناقصة، وكذلك يكتب بعض الأحيان معلومات زائدة من عنده، لذلك تحتاج اجاباته إلى تأكد شخصي من مدى صحتها. || أثناء المذاكرة لم أفهم نقطة معينة ثم سألته عنها وبدت لي الاجابة غير مُقنعة وشعرت بالإحباط. | H38: T1 | M38: dependency | N38: =IF($M38="","",IF($M38=$C38,"match","OVERRIDE")) -> match | O38: T1 | P38: =IF($O38="","",IF($O38=$H38,"match","OVERRIDE")) -> match | Q38: high
A39: P038 | B39: يعزز | C39: innovation | G39: كيفية صياغة المحتوى || لا يوجد | H39: T9 | M39: innovation | N39: =IF($M39="","",IF($M39=$C39,"match","OVERRIDE")) -> match | O39: T5 | P39: =IF($O39="","",IF($O39=$H39,"match","OVERRIDE")) -> OVERRIDE | Q39: low | R39: 'يعزز' with no object. Read as elliptical for يعزز الابتكار given the question wording. | 'كيفية صياغة المحتوى' listed as a challenge the student faces -> phrasing skill (T5). Reads as T9 only if the phrase is about the model's output rather than the student's prompting.
A40: P039 | B40: برأيي يعزز الابتكار والفردية، ولكن هذا يعتمد بشكل كبير على المستخدم. لكن ما يطرحه الذكاء الإصطناعي يحتاج إلى أن يصبح أكثر توافقا مع ما أريد، وفي بعض الأحيان قد لا يكون مبتكرا بالقدر المتوقع، فيتحتم عليَّ تطوير وتغيير ما طرحه. | C40: conditional | G40: عدم فهم المطلوب منه بشكل جيد، والاختصار في المعلومات، وعدم دقة المعلومات، والضعف الكبير في جانب تحليل اللغة العربية من جوانب مختلفة كالإملاء والإعراب. || استخدمت chat gpt في التحقق الإملائي من كلمة لأرى مدى إمكانيتة ودقته في تطبيق القواعد الإملائية بعد أن قدمت له قواعد كتابة الهمزة المتوسطة، فأخطأ أخطاء فادحة بكتابة الكلمات التي قدمتها له. | H40: T1,T2 | M40: conditional | N40: =IF($M40="","",IF($M40=$C40,"match","OVERRIDE")) -> match | O40: T1,T2 | P40: =IF($O40="","",IF($O40=$H40,"match","OVERRIDE")) -> match | Q40: high
...

Sheet run_findings
A1: Findings from the inter-model run of 2026-09-04
A2: Read this before writing up. Inter-model agreement is not intercoder reliability; these findings describe how two models behaved, not whether the codes are correct.
A4: CONFIGURATION
A5: annotator A | B5: openai:gpt-5.5 | D5: coded 141 of 145
A6: annotator B | B6: gemini:gemini-2.5-pro | D6: coded 145 of 145
A7: adjudicator | B7: gemini:gemini-3-flash-preview | D7: 22 disputed units; saw codes anonymised and order-shuffled, never model identity
A8: independence caveat | D8: Annotator B and the adjudicator are the same lab. This is a pilot configuration, not three independent annotators. Replace one with a third lab before reporting as such.
A10: HEADLINE FIGURES
A11: units coded by both | B11: 141 | C11: of 145 | D11: 4 units lost to empty responses — see below
A12: stance agreement | B12: 0.9929 | C12: alpha 0.9892 | D12: At ceiling. Interrogate rather than report flat: see the keyword-trap test below.
A13: themes exact-set | B13: 0.8511 | C13: alpha 0.8319 | D13: All real disagreement lives here.
A15: MISSING UNITS — all four from annotator A
A16: participant_id | B16: A | C16: B | D16: stance_text
A17: P029 | B17: (empty) | C17: innovation | D17: قد يعزز الابتكار والفرديه على المدى الطويل
A18: P046 | B18: (empty) | C18: dependency | D18: الاعتمادية
A19: P053 | B19: (empty) | C19: conditional | D19: هو "سلاح ذو حدين"؛ فقد يؤدي للاعتمادية إذا اكتفى الطالب بالمخرجات الجاهزة، لكنه يعزز الابتكار إذا استُخدم كـ "مساعد بحثي
A20: P091 | B20: (empty) | C20: conditional | D20: يعزز الابتكارية والفردية في ضوء المسموح...
D21: Not random: every failure is GPT, none is Gemini. Re-run these four, or report n=141 and state the loss.
A23: KEYWORD-TRAP TEST — does agreement reflect the rules or shared surface bias?
A24: participant_id | B24: rule-correct | C24: suggestion said | D24: A / B / verdict
A25: P005 | B25: dependency (R-S3 negation) | C25: (blank) | D25: A=dependency B=dependency -> both correct
A26: P051 | B26: conditional (R-S1 bare both) | C26: uncodable | D26: A=conditional B=conditional -> both correct
A27: P058 | B27: conditional (R-S1 bare both) | C27: uncodable | D27: A=conditional B=conditional -> both correct
A28: P098 | B28: conditional (R-S1 bare both) | C28: uncodable | D28: A=conditional B=conditional -> both correct
A29: P139 | B29: conditional (R-S1 bare both) | C29: uncodable | D29: A=conditional B=conditional -> both correct
D30: All five correct, and all five diverge from the suggestion layer in the direction the rules require. Surface-keyword anchoring would have reproduced the suggestion layer's errors instead. This is the evidence that the stance alpha is not merely shared bias.
A32: INDEPENDENT CHECK ON THE 30 THEME OVERRIDES
A33: models backed the override | B33: 21 | D33: Both models, blind, reached the code the audit proposed.
A34: models backed the suggestion | B34: 0 | D34: Not once did they side with the layer flagged as inconsistent.
A35: models chose a third code | B35: 3 | D35: All three were medium-confidence overrides.
A36: of the 21: marked low-confidence | B36: 7 | D36: The rules held up better than the confidence ratings did.
A38: WHERE THE DISPUTES ACTUALLY FELL
A39: theme | B39: times in dispute | D39: comment
A40: T5 | B40: 8 | D40: The real fault line. Cause of amendment R-T5b.
A41: T1 | B41: 6 | D41: Expected.
A42: T2 | B42: 3 | D42: Far less than predicted.
A43: T3 | B43: 2
A44: T7 | B44: 1
A45: T4 | B45: 1
A46: T6 | B46: 1
...

Sheet recode_queue
A1: Units to re-run before pooling results
A2: Two groups: calls that returned nothing, and units whose codes depend on the superseded rule R-T5 v1. Re-run these under R-T5b, or exclude them and say so.
A4: participant_id | B4: reason | C4: A_themes | D4: B_themes | E4: barrier_text
A5: P029 | B5: empty response from annotator A | D5: T1,T2 | E5: عدم وجود اداه تجلب معلومات دقيقه عن اللغه العربيه || توليد اعرابات خاطئه وغير منطقيه اصلا
A6: P046 | B6: empty response from annotator A | D6: T1,T2 | E6: الدقة في التحليل اللغوي العميق: رغم تطور النماذج، إلا أنها قد تخفق أحياناً في ضبط "أواخر الكلم" أو إعراب الجمل المعقدة التي تعتمد على السياق البعيد أو
A7: P053 | B7: empty response from annotator A | D7: T2,T3 | E7: أبرز التحديات هي "عدم الدقة في ضبط النصوص وتشكيلها" بشكل صحيح تماماً، بالإضافة إلى ضعف قدرة بعض الأدوات على فهم "المجاز والكناية" وخصوصية الأدب العربي
A8: P091 | B8: empty response from annotator A | D8: T3,T5 | E8: عدم توافق الذكاء الاصطناعي مع مدخلاتي، وإعطاء نتيجة بعيدة من المطلوب. || إنشاء بيوت شعرية غير موجودة قام الذكاء بتوليدها من عقله.
A9: P004 | B9: T5 boundary — depends on superseded R-T5 v1 | C9: T1,T4 | D9: T1,T4,T5 | E9: عدم توفر مصادر موثوقة || عدم الفهم السريع،و قلة الدقة في المعاني
A10: P008 | B10: T5 boundary — depends on superseded R-T5 v1 | C10: T2 | D10: T5 | E10: لا يفهم كثيرا ف اللغة || !
A11: P019 | B11: T5 boundary — depends on superseded R-T5 v1 | C11: T1 | D11: T1,T5 | E11: عدم دقة المعلومات اللتي يقدمها و ضعف الفهم للسياق احيانا || لا توجد
A12: P059 | B12: T5 boundary — depends on superseded R-T5 v1 | C12: T1 | D12: T1,T5 | E12: أحيانا يكون غبيا لا يفهم || يحلل على راسه ويقلب المعاني فوق تحت
A13: P063 | B13: T5 boundary — depends on superseded R-T5 v1 | C13: T1,T2,T4 | D13: T1,T2,T4,T5 | E13: من أبرز التحديات صعوبة التأكد من دقة بعض المعلومات أحيانًا، خاصة في التحليل الأدبي أو الشروح اللغوية، إضافة إلى أن بعض الأدوات تقدّم إجابات عامة لا تر
A14: P064 | B14: T5 boundary — depends on superseded R-T5 v1 | C14: T1 | D14: T1,T5 | E14: صعوبتها || خطا في المعلومات
A15: P134 | B15: T5 boundary — depends on superseded R-T5 v1 | C15: T1 | D15: T1,T5 | E15: الأخطاء || عدم التفكير والأعتماد عليها
A16: P142 | B16: T5 boundary — depends on superseded R-T5 v1 | C16: T1,T4 | D16: T1,T4,T5 | E16: عدم دقة المعلومات، واختلاف الإجابة مع اختلاف صياغة السؤال وإن كانت الفكرة واحدة || عدم الدقة! والمصادر الموهومة!

Sheet validation_sample
A1: Human validation sample - code these blind
A2: The model's codes are deliberately NOT shown on this sheet. If the human coder sees them, the agreement figure is worthless. Code from the Arabic text and the codebook only, then run the comparison below. Stratified random draw, seed 20260904, presented in shuffled order.
A4: participant_id | B4: stance_text | C4: barrier_text | D4: human_stance | E4: human_themes | F4: human_note
A5: P104 | B5: =coding!$B105 -> يؤدي إلى الاعتماديه | C5: =coding!$G105 -> لا توجد تحديات || عدم الدقة في المعلومات التي تقدمها هذه البرامج
A6: P006 | B6: =coding!$B7 -> يعزز الابتكار الفردي | C6: =coding!$G7 -> صعوبة فهمه للغة || لا يفهم قواعد اللغة العربية كثيرًا
A7: P077 | B7: =coding!$B78 -> يعزز الابتكار | C7: =coding!$G78 -> الإجابات غير دقيقة || لا توجد
A8: P019 | B8: =coding!$B20 -> يعتمد على طريقة الاستخدام | C8: =coding!$G20 -> عدم دقة المعلومات اللتي يقدمها و ضعف الفهم للسياق احيانا || لا توجد
A9: P032 | B9: =coding!$B33 -> الابتكار | C9: =coding!$G33 -> لا يتعرف على قواعد العربية || لا يتعمق في الاجابة
A10: P046 | B10: =coding!$B47 -> الاعتمادية | C10: =coding!$G47 -> الدقة في التحليل اللغوي العميق: رغم تطور النماذج، إلا أنها قد تخفق أحياناً في ضبط "أواخر الكلم" أو إعراب الجمل المعقدة التي تعتمد على السياق البعيد أو التقدير (كالمحذوفات والتقديم والتأخير)، مما قد يؤدي لنتائج غير دقيقة في التخصصات اللغوية الدقيقة. || من أبرز التجارب السلبية هي "الهلوسة اللغوية في الإعراب"؛ حيث طلبتُ من الذكاء الاصطناعي إعراب بيت شعري يتضمن "تقديمًا وتأخيرًا" معقدًا، فقام بإعراب الكلمات بشكل منفرد وصحيح ظاهريًا، لكنه أخطأ تمامًا في ربط المعنى، فجعل "الفاعل" "مفعولًا به" لمجرد أنه تقدم عليه في الترتيب. هذه التجربة كانت مربكة لأن الإجابة صيغت بثقة تامة، مما قد يضلل الطالب الذي لا يملك خلفية قوية، وأثبتت لي أن الذكاء الاصطناعي أحيانًا يفتقر إلى "الذوق السياقي"
A11: P111 | B11: =coding!$B112 -> كلاهما، حيث ربما يعتمد عليه الطلاب في استخراج الأفكار والعناوين والمصادر لكنه يعزز من تعزيز فكر الطالب وطريقته للبحث وأن ينظر للأأمور من زاوية أخرى دائمًا | C11: =coding!$G112 -> أنه يعطي أحيانًا معلومات غير دقيقة ويظن أنها صحيحة || عدم دقة المعلومات وأنه أبدًا لا يعترف بالخطأ أو قول لا اعرف الاجابة
A12: P073 | B12: =coding!$B74 -> يعزز الابتكار إذا استُخدم كأداة "مساعدة" للبحث والتحليل، لكنه قد يؤدي للاعتمادية إذا استُخدم كبديل كلي عن التفكير النقدي والجهد الشخصي. | C12: =coding!$G74 -> ضعف الدقة في التعامل مع القواعد النحوية المعقدة، ومحدودية قدرة الأدوات الحالية على فهم السياقات البلاغية العميقة للنصوص التراثية. || الحصول على إجابات تحتوي على "هلوسة لغوية"، مثل ابتكار قواعد نحوية غير صحيحة أو نسب أبيات شعرية لشعراء لم يكتبوها.
A13: P142 | B13: =coding!$B143 -> بالنسبة لي يساعدني في التحليل والابتكار وسعة الأفق | C13: =coding!$G143 -> عدم دقة المعلومات، واختلاف الإجابة مع اختلاف صياغة السؤال وإن كانت الفكرة واحدة || عدم الدقة! والمصادر الموهومة!
A14: P138 | B14: =coding!$B139 -> يعتمد على استخدام الشخص | C14: =coding!$G139 -> عدم توفرها بالجودة العالية || لا يجيد اللغة العربية جيدا
A15: P079 | B15: =coding!$B80 -> على حسب الفرد، يمكن أن يتشاركا العلمية الإبداعية، فالآلة والذكاء الاصطناعي وحده لا يجلبُ إبداعًا، إنما هو يحلل ويخطط ويقترح أسرعن لكن الجانب الإبداعي والتفكيري يكون عنج الإنسان، وإذا استخدمه الإنسان بطريقة صحيحة يمكن أن يصل لدرجة كبيرة من الإتقان والإبتكار والإبداع. | C15: =coding!$G80 -> صعوبة فهمه للعربية، ويجب إدخال معلومات صحيحة له، لأنه قد يأتي بعلمٍ وحده، أو يفسّر شيئًا خاطئًا بطريقة تجعلك تقتنع به، وكذلك محدودية الوصول المجاني || لا يستطيع تحليل الأبيات الشعرية، عندما لم أجد شرحًا لا في الكتب ولا في الشبكة المعلوماتية، استنعت بالذكاء، لكنه لا يحلل بشكل صحيح
A16: P065 | B16: =coding!$B66 -> الاعتمادية | C16: =coding!$G66 -> لاتوجد || تحليل الشعر بشكل غير صحيح
A17: P025 | B17: =coding!$B26 -> كلاهما | C17: =coding!$G26 -> عدم الدقة في المعلومات-كثرة الأخطاء || معلومة خاطئة
A18: P014 | B18: =coding!$B15 -> الآثنين معاً | C18: =coding!$G15 -> قلة المعرفه به و المعلومات المغلوطه || التحليل الغير دقيق مثلا
A19: P024 | B19: =coding!$B25 -> قد يؤدي إلى الاعتمادية في حال عدم التدقيق خلفه وعدم التأكد، ولكن قد يعزز روح النقد لديك في حال تتبعت المعلومة وتأكدت من صحتها خلفه. | C19: =coding!$G25 -> دقة المعلومات، وموثوقيتها || بعض المعلومات التي يأتي بها خاطئة، أو لادخل لها بالموضوع الذي أبحث عنه.
A20: P145 | B20: =coding!$B146 -> يعزز الفردية والابتكار | C20: =coding!$G146 -> عدم إعطاء الطالب المعلومة الدقيقة والكافية لما يبحث عنه || عند البحث عن اعراب جملة ما فإنه يقوم بإعرابها بشكل خاطئ وغير دقيق
A21: P096 | B21: =coding!$B97 -> قد يؤدي إلى الاعتمادية عند استخدامه بشكل مبالغ، ولكنه أحيانًا يعزز من الابتكار عندما يبدأ بإعطائك أفكار إضافية على فكرتك الأساسية مما يعزز من قوتها. | C21: =coding!$G97 -> الحصول على معلومات غير موثوقة. || شرح سطحي للأبيات الشعرية، وكذلك بالنسبة للبلاغة، كما أنه يخلط كثيرًا بين قواعد النحو والصرف.
A22: P089 | B22: =coding!$B90 -> الاعتمادية | C22: =coding!$G90 -> الاعتماد عليه أحيانا مثلا في تحليل نص أدبي يحد من قدرتك على التفكير ويقيدك بما هو موجود أمامك من شرح أو إيضاح أو تحليل || عدم الدقة فيه خاصة في الإعراب والبلاغة
A23: P009 | B23: =coding!$B10 -> كلاهما | C23: =coding!$G10 -> التدقيق اللغوي والاملائي || دقة المراجع
A24: P087 | B24: =coding!$B88 -> أرى أنه يعتمد على كيفية الإستخدام | C24: =coding!$G88 -> دقة الإجابات و ندرة المراجع الموثوقة التي يعتمد عليها الذكاء الاصطناعي في الإجابة || عندما طلبت من الذكاء الاصطناعي ان يحل لي سؤال نحوي يجمع بين أكثر من قاعدة لم يستطع حله بالشكل الصحيح
A25: P053 | B25: =coding!$B54 -> هو "سلاح ذو حدين"؛ فقد يؤدي للاعتمادية إذا اكتفى الطالب بالمخرجات الجاهزة، لكنه يعزز الابتكار إذا استُخدم كـ "مساعد بحثي" لتوليد أفكار أولية، أو للمقارنة بين النصوص، أو لتنظيم البيانات الضخمة، مما يفرغ ذهن الباحث للتحليل الإبداعي العميق. | C25: =coding!$G54 -> أبرز التحديات هي "عدم الدقة في ضبط النصوص وتشكيلها" بشكل صحيح تماماً، بالإضافة إلى ضعف قدرة بعض الأدوات على فهم "المجاز والكناية" وخصوصية الأدب العربي القديم، مما قد يؤدي إلى تفسيرات سطحية أو خاطئة أحياناً. || واجهتُ تجربة قام فيها الذكاء الاصطناعي بـ "اختلاق" أبيات شعرية ونسبها لشاعر جاهلي، أو خلطه بين قواعد النحو لمدرسة البصرة والكوفة في مسألة خلافية واحدة، مما جعلني أدرك أهمية التحقق من المصادر وعدم التسليم المطلق بصحة النتائج.
A26: P064 | B26: =coding!$B65 -> لا | C26: =coding!$G65 -> صعوبتها || خطا في المعلومات
A27: P070 | B27: =coding!$B71 -> يعزز الابتكار | C27: =coding!$G71 -> المعرفة || كتابة الشعر
A28: P042 | B28: =coding!$B43 -> يؤدي إلى الاعتمادية | C28: =coding!$G43 -> الحصول على إجابات دقيقة || كثيرا ما يؤلف من عنده خاصة الشواهد
A29: P092 | B29: =coding!$B93 -> يعزز الابتكار | C29: =coding!$G93 -> . || الخلط بي القواعد النحوية والبلاغية والصرفية
A30: P093 | B30: =coding!$B94 -> الاثنان معًا يعتمد على الفرد نفسه | C30: =coding!$G94 -> عدم دقة معلومات الذكاء الاصطناعي || المعلومات المغلوطة
A31: P034 | B31: =coding!$B35 -> هذا الأمر نسبي و يعتمد على عقلية من يستخدمه | C31: =coding!$G35 -> أنه لا يفقه اللغة العربية بالشكل الذي أتطلع له || طلبت منه مساعدتي في حل واجب منزلي و لم أحصل في هذا الواجب على درجة كاملة مثلما توقعت (اعتمدت على الذكاء الاصطناعي بنسبة ٩٨% تقريبا) و هذا عزز نبوءة دكتور المقرر أن الذكاء الاصطناعي لن يفيدنا في حل ذلك الواجب، و قد كنت أحاول إثبات العكس...
A32: P005 | B32: =coding!$B6 -> يهدم الابتكار والفردية | C32: =coding!$G6 -> لا يمكن الاعتماد عليه في الدراسة، يمكن استخدامه فقط للبحث عن معلومات سطحية، ولا يصلح لشيء أعمق من ذلك || لا يستطيع الذكاء الاصطناعي التعامل مع اللغة العربية الا في ابسط الحالات
A33: P072 | B33: =coding!$B73 -> يعزز الابتكاريع | C33: =coding!$G73 -> وايد تحديات || ما يعرف يعرب
A34: P116 | B34: =coding!$B117 -> على حسب الشخص | C34: =coding!$G117 -> عدم التيقن من اجابه الذكاء الاصطناعي فتارة يصيب وتارة يخطئ || اردت البحث عن معلومه واعطاني معلومات خاطئة
A35: P040 | B35: =coding!$B41 -> - | C35: =coding!$G41 -> - || -
A36: P062 | B36: =coding!$B63 -> هو وسط بين هذ وذاك ويرجع في الأخير إلى كيفية استعمال الشخص له والغرض والهدف منه فقد يؤدي إلى الاعتمادية بشكل كبير إذا استعمله الشخص وقام بنسخ المعلومات ونسقها دون قراءتها ومعالجتها وخصوصا في آداء البحوث وقد يستخدمه الشخص في تلقي الأفكار فقط بينهما يقول بمعالجتها وتحليلها بنفسه فقد يدفعه ذلك للابتكار والاعتماد على النفس | C36: =coding!$G63 -> المعلومات غير دقيقة في بعض الأحيان ، ولا يتناول التحليل العميق || في تحليل النصوص وفهم المعنى العام من البيت فيساعد على تحليله وفهمه بلاغيا
A37: P129 | B37: =coding!$B130 -> يعزز الابتكار والتفكير الفردي | C37: =coding!$G130 -> عدم استطاعته قراءة الكتب الالكترونية وتحديد رقم الصفحات || التجربة السلبية دائماً تكمن في الإعراب، وكذلك تحديد رقم الصفحات والإجابات المتكررة.
A38: P044 | B38: =coding!$B45 -> يؤدي إلى الاعتمادية بشكل اكبر. | C38: =coding!$G45 -> عدم دقة المعلومات || عدم دقة المعلومات و التحليل .
A39: P140 | B39: =coding!$B141 -> الجانبان | C39: =coding!$G141 -> الأخطاء النحوية والصرفية || لا يوجد
A40: P051 | B40: =coding!$B52 -> هذا وهذا | C40: =coding!$G52 -> - || يهرف بما لا يعرف في النحو والاشتقاق
A42: AGREEMENT vs MODEL CODES (fills in as the sample is coded)
...

Sheet codebook
A1: item | B1: code | C1: label | D1: definition
A2: Stance item (Q4): does AI use lead to dependency, or foster innovation and individuality? | B2: dependency | C2: Dependency | D2: AI use causes reliance, laziness, or weakens the student.
A3: Stance item (Q4): does AI use lead to dependency, or foster innovation and individuality? | B3: innovation | C3: Innovation and individuality | D3: AI use fosters innovation, creativity or individuality.
A4: Stance item (Q4): does AI use lead to dependency, or foster innovation and individuality? | B4: conditional | C4: Conditional | D4: Both, or the outcome depends on how, how much, or by whom the tool is used.
A5: Stance item (Q4): does AI use lead to dependency, or foster innovation and individuality? | B5: uncodable | C5: No codable stance | D5: Empty, evasive, off-topic, or expresses no stance.
A6: Barrier themes (Q2 + Q6): problems encountered using generative AI for Arabic study | B6: T1 | C6: Inaccurate / unreliable output | D6: Output is wrong, imprecise, unreliable or misleading (generic inaccuracy).
A7: Barrier themes (Q2 + Q6): problems encountered using generative AI for Arabic study | B7: T2 | C7: Weak Arabic grammar & morphology | D7: Specifically weak at Arabic grammar/syntax (iʿrāb), morphology, vocalisation, prosody or rhetoric, or produces stilted Arabic.
A8: Barrier themes (Q2 + Q6): problems encountered using generative AI for Arabic study | B8: T3 | C8: Hallucinated literary attribution | D8: Attributes verses, poems or texts to the wrong poet or author, or invents verses.
A9: Barrier themes (Q2 + Q6): problems encountered using generative AI for Arabic study | B9: T4 | C9: Fabricated / missing references | D9: Invents or cannot supply references, sources, books or citations.
A10: Barrier themes (Q2 + Q6): problems encountered using generative AI for Arabic study | B10: T5 | C10: Weak prompting / appraisal skill | D10: The student's own lack of skill in prompting, phrasing or judging output.
A11: Barrier themes (Q2 + Q6): problems encountered using generative AI for Arabic study | B11: T6 | C11: Few Arabic-supporting tools | D11: No or few tools that support Arabic; tools are English-oriented.
A12: Barrier themes (Q2 + Q6): problems encountered using generative AI for Arabic study | B12: T7 | C12: Faculty / institutional resistance | D12: Teachers, department or university discourage, forbid or penalise use.
... A14: Barrier themes (Q2 + Q6): problems encountered using generative AI for Arabic study | B14: T9 | C14: Other / none | D14: No barrier stated, or a barrier outside the scheme above.
A16: DECISION RULES (added after audit; resolve the cases the definitions above leave open)
A17: rule | B17: applies to | C17: rule | D17: why it was needed
A18: R-S1 | B18: stance | C18: Any bare 'both' formulation is conditional, not uncodable: كلاهما، الاثنين، الأثنين، الاثنان معا، الأمرين معا، الجانبان، هذا وهذا، بين الاعتماد والابتكار. | D18: The definition already puts 'both' under conditional, but bare one-word forms were being read as absence of stance. P051, P058, P139 were coded uncodable while P009, P067, P118 with the same meaning were coded conditional.
A19: R-S2 | B19: stance | C19: Bare محايد with no elaboration is uncodable. محايد followed by elaboration is coded on the elaboration. | D19: 'Neutral' is a refusal to choose; 'neutral because it has both roles' is a both-statement. Separates P068 from P015 and P098.
A20: R-S3 | B20: stance | C20: Code the predicate, not the keyword. A pole word inside a negation belongs to the opposite pole. | D20: P005 'يهدم الابتكار والفردية' (destroys innovation) was coded innovation by keyword.
A21: R-S4 | B21: stance | C21: One pole stated with an explicit condition on how, how much, or by whom = conditional. | D21: Keeps P069, P075, P109, P117 consistent with the multi-pole conditionals.
A22: R-S5 | B22: stance | C22: Frequency and time hedges (قد، أحيانا، على المدى الطويل، غالبا) do NOT make a response conditional. Only usage conditions do. | D22: Without this, P029, P103 and P144 drift into conditional and the category swallows the poles.
A23: R-S6 | B23: stance | C23: Code the whole response to the last sentence. Long responses can reverse pole at the end. | D23: P122 reads as dependency for 400+ characters and concedes the innovation pole only in its final sentence.
A24: R-S7 | B24: stance | C24: Non-responsive tokens are uncodable: - . ! نعم، لا، لا اعلم، في بعض الأحيان. | D24: Consistency across P007, P008, P040, P064, P107, P110, P134.
A25: R-T2a | B25: themes | C25: T2 applies whenever the response names an Arabic linguistic or literary domain (نحو، صرف، إعراب، بلاغة، عروض، إملاء، تشكيل/ضبط، تحليل النصوص أو الأبيات أو الشعر، قواعد اللغة العربية) or says the model is weak at Arabic in general. T1 applies to accuracy complaints with no domain named. Both codes when both are present. | D25: This boundary is the single largest source of coder disagreement in the set. See gap G1.
A26: R-T2b | B26: themes | C26: Orthography (إملاء) and language proofreading (التدقيق اللغوي) fall under T2. | D26: Not listed in the T2 definition; affects P009 and P039.
A27: R-T2c | B27: themes | C27: T2 = the model performs badly at Arabic. T6 = tools do not exist, do not support Arabic, or are built for English. | D27: P029, P122, P133 and P141 complain about tool availability, not model competence.
A28: R-T4 | B28: themes | C28: T4 covers wrong or unverifiable bibliographic detail, including volume and page numbers, not only invented titles. | D28: P127 and P129 report wrong page references and were coded T1/T2 only.
... A32: R-TU | B32: themes | C32: barrier_text holds two survey answers joined by ||. Code the union of both parts. If one part is لا يوجد or -, code the other part only. | D32: Otherwise coders differ on whether the second clause counts.
A34: OPEN GAPS - decide these before the main coding pass
A35: gap | B35: issue | C35: affected units | D35: options
A36: G1 | B36: The T1 / T2 boundary. Around 40% of units contain both a generic accuracy complaint and a named Arabic domain, so the choice between T1, T2 and T1+T2 is doing most of the work. | C36: P008, P062, P065, P069, P084, P123 and roughly 55 double-coded units | D36: Adopt R-T2a as written (double-code freely), or make T2 exclusive of T1 so the two never co-occur. The second gives cleaner reliability but loses the generic-inaccuracy signal.
A37: G2 | B37: T8 was defined for cost and access, but several responses report technical failure (hanging, slowness, file-size and image limits). | C37: P016, P017, P036, P083, P137 | D37: Adopt R-T8 as written, or keep T8 narrow and send these to T9.
A38: G3 | B38: Over-reliance harming the student's own thinking has no theme. It is not inaccuracy (T1) and not a prompting or appraisal skill (T5). | C38: P089, P106, P122, P134, and it is the whole substance of P122 | D38: Add T10 'over-reliance / erosion of own skill', or route these to T9 and note the loss.
A39: G4 | B39: T9 merges 'no barrier stated' with 'a barrier outside the scheme' and with 'I do not use the tool'. | C39: P003, P030, P040, P054, P070, P110, P112, P114 | D39: Split into T9a (none stated / non-user) and T9b (other), or accept the merge and report it.
A40: R-T5b | B40: themes | C40: T5 covers ONLY the student's own skill: their prompting, phrasing, or ability to judge output. A complaint that the MODEL fails to understand Arabic input is not T5 — code it T2 if a linguistic or literary domain is named, otherwise T1. Distinguishing test: whose deficiency does the sentence assert? 'لا أستطيع صياغة الأوامر' is the student (T5). 'لا يفهم ما أقول' and 'ضعف الفهم للسياق' are the model (T1/T2). | D40: AMENDMENT 2026-09-04, post-hoc. R-T5 v1 said 'it does not understand what I want is coded T5', which conflated the two. T5 accounted for 8 of the 22 inter-model disputes — more than T1 (6) and T2 (3) — because both readings were defensible under v1. Units coded under v1 must be re-run before v1 and v2 codes are pooled.
A42: G5 | B42: The T5 boundary, not the T1/T2 boundary, is the main fault line. Predicted before the run to be T1/T2; the run showed otherwise. | C42: P004, P008, P019, P059 and 4 further disputed units — see recode_queue | D42: Resolved by amendment R-T5b. Re-run the affected units, or report them as unresolved and exclude from the theme agreement figure.

Sheet reliability
A1: Intercoder reliability
A2: Every figure below is a live formula over the coding sheet. They read 0 or blank until the human coders fill in columns D, E, I and J. Nothing here is precomputed.
A4: STANCE - coder 1 vs coder 2
A5: Units coded by both | B5: =SUMPRODUCT((coding!$D$2:$D$146<>"")*(coding!$E$2:$E$146<>"")) -> 5
A6: Agreements | B6: =SUMPRODUCT((coding!$D$2:$D$146<>"")*(coding!$E$2:$E$146<>"")*(coding!$D$2:$D$146=coding!$E$2:$E$146)) -> 2
A7: Observed agreement (Po) | B7: =IFERROR($B$6/$B$5,"") -> 0.4
A9: category | B9: n coder 1 | C9: n coder 2 | D9: p1 x p2 | E9: n1 + n2
A10: dependency | B10: =COUNTIFS(coding!$D$2:$D$146,$A10,coding!$E$2:$E$146,"<>") -> 2 | C10: =COUNTIFS(coding!$E$2:$E$146,$A10,coding!$D$2:$D$146,"<>") -> 1 | D10: =IFERROR($B10/$B$5*$C10/$B$5,"") -> 0.08 | E10: =$B10+$C10 -> 3
A11: innovation | B11: =COUNTIFS(coding!$D$2:$D$146,$A11,coding!$E$2:$E$146,"<>") -> 1 | C11: =COUNTIFS(coding!$E$2:$E$146,$A11,coding!$D$2:$D$146,"<>") -> 2 | D11: =IFERROR($B11/$B$5*$C11/$B$5,"") -> 0.08 | E11: =$B11+$C11 -> 3
A12: conditional | B12: =COUNTIFS(coding!$D$2:$D$146,$A12,coding!$E$2:$E$146,"<>") -> 1 | C12: =COUNTIFS(coding!$E$2:$E$146,$A12,coding!$D$2:$D$146,"<>") -> 1 | D12: =IFERROR($B12/$B$5*$C12/$B$5,"") -> 0.04 | E12: =$B12+$C12 -> 2
A13: uncodable | B13: =COUNTIFS(coding!$D$2:$D$146,$A13,coding!$E$2:$E$146,"<>") -> 1 | C13: =COUNTIFS(coding!$E$2:$E$146,$A13,coding!$D$2:$D$146,"<>") -> 1 | D13: =IFERROR($B13/$B$5*$C13/$B$5,"") -> 0.04 | E13: =$B13+$C13 -> 2
A14: Expected agreement (Pe) | B14: =SUM($D$10:$D$13) -> 0.24
A15: Cohen's kappa | B15: =IFERROR(($B$7-$B$14)/(1-$B$14),"") -> 0.21052632 | G15: Reported figure for a 2-coder nominal scheme.
A16: n values (2 x paired units) | B16: =2*$B$5 -> 10
A17: Sum of squared category totals | B17: =SUMPRODUCT($E$10:$E$13,$E$10:$E$13) -> 26
A18: Expected disagreement (De) | B18: =IFERROR(($B$16^2-$B$17)/($B$16*($B$16-1)),"") -> 0.82222222
A19: Krippendorff's alpha (nominal) | B19: =IFERROR(1-(1-$B$7)/$B$18,"") -> 0.27027027 | G19: Alpha and kappa differ slightly at this n; report whichever the target journal expects.
A21: BARRIER THEMES - coder 1 vs coder 2
A22: Units coded by both | B22: =SUMPRODUCT(themes_matrix!$B$2:$B$146,themes_matrix!$C$2:$C$146) -> 0
A23: Exact set matches | B23: =SUM(themes_matrix!$AI$2:$AI$146) -> 0
A24: Exact set agreement | B24: =IFERROR($B$23/$B$22,"")
A25: Mean Jaccard overlap | B25: =IFERROR(SUM(themes_matrix!$AH$2:$AH$146)/$B$22,"") | G25: Exact match is harsh for multi-label data; Jaccard is the fairer headline, kappa per theme the fairest.
A27: theme | B27: n coder 1 | C27: n coder 2 | D27: agreements | E27: Po | F27: kappa
A28: T1 | B28: =SUMPRODUCT(themes_matrix!$B$2:$B$146,themes_matrix!$C$2:$C$146,themes_matrix!$E$2:$E$146) -> 0 | C28: =SUMPRODUCT(themes_matrix!$B$2:$B$146,themes_matrix!$C$2:$C$146,themes_matrix!$N$2:$N$146) -> 0 | D28: =SUMPRODUCT(themes_matrix!$B$2:$B$146,themes_matrix!$C$2:$C$146,--(themes_matrix!$E$2:$E$146=themes_matrix!$N$2:$N$146)) -> 0 | E28: =IFERROR($D28/$B$22,"") | F28: =IFERROR(($E28-(($B28/$B$22)*($C28/$B$22)+(1-$B28/$B$22)*(1-$C28/$B$22)))/(1-(($B28/$B$22)*($C28/$B$22)+(1-$B28/$B$22)*(1-$C28/$B$22))),"")
A29: T2 | B29: =SUMPRODUCT(themes_matrix!$B$2:$B$146,themes_matrix!$C$2:$C$146,themes_matrix!$F$2:$F$146) -> 0 | C29: =SUMPRODUCT(themes_matrix!$B$2:$B$146,themes_matrix!$C$2:$C$146,themes_matrix!$O$2:$O$146) -> 0 | D29: =SUMPRODUCT(themes_matrix!$B$2:$B$146,themes_matrix!$C$2:$C$146,--(themes_matrix!$F$2:$F$146=themes_matrix!$O$2:$O$146)) -> 0 | E29: =IFERROR($D29/$B$22,"") | F29: =IFERROR(($E29-(($B29/$B$22)*($C29/$B$22)+(1-$B29/$B$22)*(1-$C29/$B$22)))/(1-(($B29/$B$22)*($C29/$B$22)+(1-$B29/$B$22)*(1-$C29/$B$22))),"")
A30: T3 | B30: =SUMPRODUCT(themes_matrix!$B$2:$B$146,themes_matrix!$C$2:$C$146,themes_matrix!$G$2:$G$146) -> 0 | C30: =SUMPRODUCT(themes_matrix!$B$2:$B$146,themes_matrix!$C$2:$C$146,themes_matrix!$P$2:$P$146) -> 0 | D30: =SUMPRODUCT(themes_matrix!$B$2:$B$146,themes_matrix!$C$2:$C$146,--(themes_matrix!$G$2:$G$146=themes_matrix!$P$2:$P$146)) -> 0 | E30: =IFERROR($D30/$B$22,"") | F30: =IFERROR(($E30-(($B30/$B$22)*($C30/$B$22)+(1-$B30/$B$22)*(1-$C30/$B$22)))/(1-(($B30/$B$22)*($C30/$B$22)+(1-$B30/$B$22)*(1-$C30/$B$22))),"")
A31: T4 | B31: =SUMPRODUCT(themes_matrix!$B$2:$B$146,themes_matrix!$C$2:$C$146,themes_matrix!$H$2:$H$146) -> 0 | C31: =SUMPRODUCT(themes_matrix!$B$2:$B$146,themes_matrix!$C$2:$C$146,themes_matrix!$Q$2:$Q$146) -> 0 | D31: =SUMPRODUCT(themes_matrix!$B$2:$B$146,themes_matrix!$C$2:$C$146,--(themes_matrix!$H$2:$H$146=themes_matrix!$Q$2:$Q$146)) -> 0 | E31: =IFERROR($D31/$B$22,"") | F31: =IFERROR(($E31-(($B31/$B$22)*($C31/$B$22)+(1-$B31/$B$22)*(1-$C31/$B$22)))/(1-(($B31/$B$22)*($C31/$B$22)+(1-$B31/$B$22)*(1-$C31/$B$22))),"")
A32: T5 | B32: =SUMPRODUCT(themes_matrix!$B$2:$B$146,themes_matrix!$C$2:$C$146,themes_matrix!$I$2:$I$146) -> 0 | C32: =SUMPRODUCT(themes_matrix!$B$2:$B$146,themes_matrix!$C$2:$C$146,themes_matrix!$R$2:$R$146) -> 0 | D32: =SUMPRODUCT(themes_matrix!$B$2:$B$146,themes_matrix!$C$2:$C$146,--(themes_matrix!$I$2:$I$146=themes_matrix!$R$2:$R$146)) -> 0 | E32: =IFERROR($D32/$B$22,"") | F32: =IFERROR(($E32-(($B32/$B$22)*($C32/$B$22)+(1-$B32/$B$22)*(1-$C32/$B$22)))/(1-(($B32/$B$22)*($C32/$B$22)+(1-$B32/$B$22)*(1-$C32/$B$22))),"")
A33: T6 | B33: =SUMPRODUCT(themes_matrix!$B$2:$B$146,themes_matrix!$C$2:$C$146,themes_matrix!$J$2:$J$146) -> 0 | C33: =SUMPRODUCT(themes_matrix!$B$2:$B$146,themes_matrix!$C$2:$C$146,themes_matrix!$S$2:$S$146) -> 0 | D33: =SUMPRODUCT(themes_matrix!$B$2:$B$146,themes_matrix!$C$2:$C$146,--(themes_matrix!$J$2:$J$146=themes_matrix!$S$2:$S$146)) -> 0 | E33: =IFERROR($D33/$B$22,"") | F33: =IFERROR(($E33-(($B33/$B$22)*($C33/$B$22)+(1-$B33/$B$22)*(1-$C33/$B$22)))/(1-(($B33/$B$22)*($C33/$B$22)+(1-$B33/$B$22)*(1-$C33/$B$22))),"")
A34: T7 | B34: =SUMPRODUCT(themes_matrix!$B$2:$B$146,themes_matrix!$C$2:$C$146,themes_matrix!$K$2:$K$146) -> 0 | C34: =SUMPRODUCT(themes_matrix!$B$2:$B$146,themes_matrix!$C$2:$C$146,themes_matrix!$T$2:$T$146) -> 0 | D34: =SUMPRODUCT(themes_matrix!$B$2:$B$146,themes_matrix!$C$2:$C$146,--(themes_matrix!$K$2:$K$146=themes_matrix!$T$2:$T$146)) -> 0 | E34: =IFERROR($D34/$B$22,"") | F34: =IFERROR(($E34-(($B34/$B$22)*($C34/$B$22)+(1-$B34/$B$22)*(1-$C34/$B$22)))/(1-(($B34/$B$22)*($C34/$B$22)+(1-$B34/$B$22)*(1-$C34/$B$22))),"")
A35: T8 | B35: =SUMPRODUCT(themes_matrix!$B$2:$B$146,themes_matrix!$C$2:$C$146,themes_matrix!$L$2:$L$146) -> 0 | C35: =SUMPRODUCT(themes_matrix!$B$2:$B$146,themes_matrix!$C$2:$C$146,themes_matrix!$U$2:$U$146) -> 0 | D35: =SUMPRODUCT(themes_matrix!$B$2:$B$146,themes_matrix!$C$2:$C$146,--(themes_matrix!$L$2:$L$146=themes_matrix!$U$2:$U$146)) -> 0 | E35: =IFERROR($D35/$B$22,"") | F35: =IFERROR(($E35-(($B35/$B$22)*($C35/$B$22)+(1-$B35/$B$22)*(1-$C35/$B$22)))/(1-(($B35/$B$22)*($C35/$B$22)+(1-$B35/$B$22)*(1-$C35/$B$22))),"")
A36: T9 | B36: =SUMPRODUCT(themes_matrix!$B$2:$B$146,themes_matrix!$C$2:$C$146,themes_matrix!$M$2:$M$146) -> 0 | C36: =SUMPRODUCT(themes_matrix!$B$2:$B$146,themes_matrix!$C$2:$C$146,themes_matrix!$V$2:$V$146) -> 0 | D36: =SUMPRODUCT(themes_matrix!$B$2:$B$146,themes_matrix!$C$2:$C$146,--(themes_matrix!$M$2:$M$146=themes_matrix!$V$2:$V$146)) -> 0 | E36: =IFERROR($D36/$B$22,"") | F36: =IFERROR(($E36-(($B36/$B$22)*($C36/$B$22)+(1-$B36/$B$22)*(1-$C36/$B$22)))/(1-(($B36/$B$22)*($C36/$B$22)+(1-$B36/$B$22)*(1-$C36/$B$22))),"")
A39: MODEL ANNOTATOR vs HUMAN CODERS
A40: Populates as the coders work. This is the comparison for the LLM-as-annotator arm; it is not intercoder reliability and must not be reported as such.
A41: Stance: model vs coder 1 | B41: =IFERROR(SUMPRODUCT((coding!$D$2:$D$146<>"")*(coding!$D$2:$D$146=coding!$M$2:$M$146))/SUMPRODUCT(--(coding!$D$2:$D$146<>"")),"") -> 0.16666667
A42: Stance: model vs coder 2 | B42: =IFERROR(SUMPRODUCT((coding!$E$2:$E$146<>"")*(coding!$E$2:$E$146=coding!$M$2:$M$146))/SUMPRODUCT(--(coding!$E$2:$E$146<>"")),"") -> 0.2
A43: Stance: model vs resolved code | B43: =IFERROR(SUMPRODUCT((coding!$F$2:$F$146<>"")*(coding!$F$2:$F$146=coding!$M$2:$M$146))/SUMPRODUCT(--(coding!$F$2:$F$146<>"")),"") -> 0
A44: Stance: model vs suggestion | B44: =SUMPRODUCT(--(coding!$N$2:$N$146="match"))/145 -> 0.96551724
A45: Themes: mean Jaccard vs coder 1 | B45: =IFERROR(SUM(themes_matrix!$AJ$2:$AJ$146)/SUMPRODUCT(themes_matrix!$B$2:$B$146),"")
A46: Themes: mean Jaccard vs coder 2 | B46: =IFERROR(SUM(themes_matrix!$AK$2:$AK$146)/SUMPRODUCT(themes_matrix!$C$2:$C$146),"")
...

Sheet adjudication
A1: Adjudication view - filter column F or K on DISAGREE
A2: Status columns are live. Enter resolutions in the yellow columns, then copy them into stance_agreed / barriers_agreed on the coding sheet.
A4: participant_id | B4: stance_text | C4: c1 stance | D4: c2 stance | E4: model stance | F4: stance status | G4: stance resolution | H4: c1 themes | I4: c2 themes | J4: model themes | K4: themes status | L4: themes resolution
A5: =coding!$A2 -> P001 | B5: =coding!$B2 -> الاعتمادية | C5: =IF(coding!$D2="","",coding!$D2) -> dependency | D5: =IF(coding!$E2="","",coding!$E2) -> dependency | E5: =IF(coding!$M2="","",coding!$M2) -> dependency | F5: =IF(OR(coding!$D2="",coding!$E2=""),"not yet coded",IF(coding!$D2=coding!$E2,"agree","DISAGREE")) -> agree | H5: =IF(coding!$I2="","",coding!$I2) | I5: =IF(coding!$J2="","",coding!$J2) | J5: =IF(coding!$O2="","",coding!$O2) -> T1 | K5: =IF(OR(coding!$I2="",coding!$J2=""),"not yet coded",IF(coding!$I2=coding!$J2,"agree","DISAGREE")) -> not yet coded
A6: =coding!$A3 -> P002 | B6: =coding!$B3 -> يؤدي إلى الاعتمادية | C6: =IF(coding!$D3="","",coding!$D3) -> conditional | D6: =IF(coding!$E3="","",coding!$E3) -> innovation | E6: =IF(coding!$M3="","",coding!$M3) -> dependency | F6: =IF(OR(coding!$D3="",coding!$E3=""),"not yet coded",IF(coding!$D3=coding!$E3,"agree","DISAGREE")) -> DISAGREE | H6: =IF(coding!$I3="","",coding!$I3) | I6: =IF(coding!$J3="","",coding!$J3) | J6: =IF(coding!$O3="","",coding!$O3) -> T1,T4 | K6: =IF(OR(coding!$I3="",coding!$J3=""),"not yet coded",IF(coding!$I3=coding!$J3,"agree","DISAGREE")) -> not yet coded
A7: =coding!$A4 -> P003 | B7: =coding!$B4 -> يؤدي إلى الاعتمادية | C7: =IF(coding!$D4="","",coding!$D4) -> uncodable | D7: =IF(coding!$E4="","",coding!$E4) -> uncodable | E7: =IF(coding!$M4="","",coding!$M4) -> dependency | F7: =IF(OR(coding!$D4="",coding!$E4=""),"not yet coded",IF(coding!$D4=coding!$E4,"agree","DISAGREE")) -> agree | H7: =IF(coding!$I4="","",coding!$I4) | I7: =IF(coding!$J4="","",coding!$J4) | J7: =IF(coding!$O4="","",coding!$O4) -> T9 | K7: =IF(OR(coding!$I4="",coding!$J4=""),"not yet coded",IF(coding!$I4=coding!$J4,"agree","DISAGREE")) -> not yet coded
A8: =coding!$A5 -> P004 | B8: =coding!$B5 -> إذا زاد استخدامه عن حده فيؤدي للاعتمادية | C8: =IF(coding!$D5="","",coding!$D5) -> dependency | D8: =IF(coding!$E5="","",coding!$E5) -> innovation | E8: =IF(coding!$M5="","",coding!$M5) -> conditional | F8: =IF(OR(coding!$D5="",coding!$E5=""),"not yet coded",IF(coding!$D5=coding!$E5,"agree","DISAGREE")) -> DISAGREE | H8: =IF(coding!$I5="","",coding!$I5) | I8: =IF(coding!$J5="","",coding!$J5) | J8: =IF(coding!$O5="","",coding!$O5) -> T1,T4 | K8: =IF(OR(coding!$I5="",coding!$J5=""),"not yet coded",IF(coding!$I5=coding!$J5,"agree","DISAGREE")) -> not yet coded
A9: =coding!$A6 -> P005 | B9: =coding!$B6 -> يهدم الابتكار والفردية | C9: =IF(coding!$D6="","",coding!$D6) -> innovation | D9: =IF(coding!$E6="","",coding!$E6) -> conditional | E9: =IF(coding!$M6="","",coding!$M6) -> dependency | F9: =IF(OR(coding!$D6="",coding!$E6=""),"not yet coded",IF(coding!$D6=coding!$E6,"agree","DISAGREE")) -> DISAGREE | H9: =IF(coding!$I6="","",coding!$I6) | I9: =IF(coding!$J6="","",coding!$J6) | J9: =IF(coding!$O6="","",coding!$O6) -> T1,T2 | K9: =IF(OR(coding!$I6="",coding!$J6=""),"not yet coded",IF(coding!$I6=coding!$J6,"agree","DISAGREE")) -> not yet coded
A10: =coding!$A7 -> P006 | B10: =coding!$B7 -> يعزز الابتكار الفردي | C10: =IF(coding!$D7="","",coding!$D7) -> conditional | D10: =IF(coding!$E7="","",coding!$E7) | E10: =IF(coding!$M7="","",coding!$M7) -> innovation | F10: =IF(OR(coding!$D7="",coding!$E7=""),"not yet coded",IF(coding!$D7=coding!$E7,"agree","DISAGREE")) -> not yet coded | H10: =IF(coding!$I7="","",coding!$I7) | I10: =IF(coding!$J7="","",coding!$J7) | J10: =IF(coding!$O7="","",coding!$O7) -> T2 | K10: =IF(OR(coding!$I7="",coding!$J7=""),"not yet coded",IF(coding!$I7=coding!$J7,"agree","DISAGREE")) -> not yet coded
A11: =coding!$A8 -> P007 | B11: =coding!$B8 -> في بعض الأحيان | C11: =IF(coding!$D8="","",coding!$D8) | D11: =IF(coding!$E8="","",coding!$E8) | E11: =IF(coding!$M8="","",coding!$M8) -> uncodable | F11: =IF(OR(coding!$D8="",coding!$E8=""),"not yet coded",IF(coding!$D8=coding!$E8,"agree","DISAGREE")) -> not yet coded | H11: =IF(coding!$I8="","",coding!$I8) | I11: =IF(coding!$J8="","",coding!$J8) | J11: =IF(coding!$O8="","",coding!$O8) -> T1,T3 | K11: =IF(OR(coding!$I8="",coding!$J8=""),"not yet coded",IF(coding!$I8=coding!$J8,"agree","DISAGREE")) -> not yet coded
A12: =coding!$A9 -> P008 | B12: =coding!$B9 -> ! | C12: =IF(coding!$D9="","",coding!$D9) | D12: =IF(coding!$E9="","",coding!$E9) | E12: =IF(coding!$M9="","",coding!$M9) -> uncodable | F12: =IF(OR(coding!$D9="",coding!$E9=""),"not yet coded",IF(coding!$D9=coding!$E9,"agree","DISAGREE")) -> not yet coded | H12: =IF(coding!$I9="","",coding!$I9) | I12: =IF(coding!$J9="","",coding!$J9) | J12: =IF(coding!$O9="","",coding!$O9) -> T2 | K12: =IF(OR(coding!$I9="",coding!$J9=""),"not yet coded",IF(coding!$I9=coding!$J9,"agree","DISAGREE")) -> not yet coded
A13: =coding!$A10 -> P009 | B13: =coding!$B10 -> كلاهما | C13: =IF(coding!$D10="","",coding!$D10) | D13: =IF(coding!$E10="","",coding!$E10) | E13: =IF(coding!$M10="","",coding!$M10) -> conditional | F13: =IF(OR(coding!$D10="",coding!$E10=""),"not yet coded",IF(coding!$D10=coding!$E10,"agree","DISAGREE")) -> not yet coded | H13: =IF(coding!$I10="","",coding!$I10) | I13: =IF(coding!$J10="","",coding!$J10) | J13: =IF(coding!$O10="","",coding!$O10) -> T2,T4 | K13: =IF(OR(coding!$I10="",coding!$J10=""),"not yet coded",IF(coding!$I10=coding!$J10,"agree","DISAGREE")) -> not yet coded
A14: =coding!$A11 -> P010 | B14: =coding!$B11 -> يعزز الابتكار و الفردية | C14: =IF(coding!$D11="","",coding!$D11) | D14: =IF(coding!$E11="","",coding!$E11) | E14: =IF(coding!$M11="","",coding!$M11) -> innovation | F14: =IF(OR(coding!$D11="",coding!$E11=""),"not yet coded",IF(coding!$D11=coding!$E11,"agree","DISAGREE")) -> not yet coded | H14: =IF(coding!$I11="","",coding!$I11) | I14: =IF(coding!$J11="","",coding!$J11) | J14: =IF(coding!$O11="","",coding!$O11) -> T3,T7 | K14: =IF(OR(coding!$I11="",coding!$J11=""),"not yet coded",IF(coding!$I11=coding!$J11,"agree","DISAGREE")) -> not yet coded
A15: =coding!$A12 -> P011 | B15: =coding!$B12 -> يعزز الابتكار | C15: =IF(coding!$D12="","",coding!$D12) | D15: =IF(coding!$E12="","",coding!$E12) | E15: =IF(coding!$M12="","",coding!$M12) -> innovation | F15: =IF(OR(coding!$D12="",coding!$E12=""),"not yet coded",IF(coding!$D12=coding!$E12,"agree","DISAGREE")) -> not yet coded | H15: =IF(coding!$I12="","",coding!$I12) | I15: =IF(coding!$J12="","",coding!$J12) | J15: =IF(coding!$O12="","",coding!$O12) -> T6 | K15: =IF(OR(coding!$I12="",coding!$J12=""),"not yet coded",IF(coding!$I12=coding!$J12,"agree","DISAGREE")) -> not yet coded
A16: =coding!$A13 -> P012 | B16: =coding!$B13 -> ممكن الاثنين | C16: =IF(coding!$D13="","",coding!$D13) | D16: =IF(coding!$E13="","",coding!$E13) | E16: =IF(coding!$M13="","",coding!$M13) -> conditional | F16: =IF(OR(coding!$D13="",coding!$E13=""),"not yet coded",IF(coding!$D13=coding!$E13,"agree","DISAGREE")) -> not yet coded | H16: =IF(coding!$I13="","",coding!$I13) | I16: =IF(coding!$J13="","",coding!$J13) | J16: =IF(coding!$O13="","",coding!$O13) -> T2 | K16: =IF(OR(coding!$I13="",coding!$J13=""),"not yet coded",IF(coding!$I13=coding!$J13,"agree","DISAGREE")) -> not yet coded
... A149: =coding!$A146 -> P145 | B149: =coding!$B146 -> يعزز الفردية والابتكار | C149: =IF(coding!$D146="","",coding!$D146) | D149: =IF(coding!$E146="","",coding!$E146) | E149: =IF(coding!$M146="","",coding!$M146) -> innovation | F149: =IF(OR(coding!$D146="",coding!$E146=""),"not yet coded",IF(coding!$D146=coding!$E146,"agree","DISAGREE")) -> not yet coded | H149: =IF(coding!$I146="","",coding!$I146) | I149: =IF(coding!$J146="","",coding!$J146) | J149: =IF(coding!$O146="","",coding!$O146) -> T1,T2 | K149: =IF(OR(coding!$I146="",coding!$J146=""),"not yet coded",IF(coding!$I146=coding!$J146,"agree","DISAGREE")) -> not yet coded

Sheet theme_counts
A1: Code frequencies - live formulas
A3: code | B3: label | C3: suggested | D3: model | E3: coder 1 | F3: coder 2 | G3: resolved
A4: T1 | B4: =IFERROR(INDEX(codebook!$C:$C,MATCH($A4,codebook!$B:$B,0)),"") -> Inaccurate / unreliable output | C4: =SUMPRODUCT(--ISNUMBER(SEARCH($A4,coding!$H$2:$H$146))) -> 108 | D4: =SUMPRODUCT(--ISNUMBER(SEARCH($A4,coding!$O$2:$O$146))) -> 106 | E4: =SUMPRODUCT(--ISNUMBER(SEARCH($A4,coding!$I$2:$I$146))) -> 0 | F4: =SUMPRODUCT(--ISNUMBER(SEARCH($A4,coding!$J$2:$J$146))) -> 0 | G4: =SUMPRODUCT(--ISNUMBER(SEARCH($A4,coding!$K$2:$K$146))) -> 0
A5: T2 | B5: =IFERROR(INDEX(codebook!$C:$C,MATCH($A5,codebook!$B:$B,0)),"") -> Weak Arabic grammar & morphology | C5: =SUMPRODUCT(--ISNUMBER(SEARCH($A5,coding!$H$2:$H$146))) -> 56 | D5: =SUMPRODUCT(--ISNUMBER(SEARCH($A5,coding!$O$2:$O$146))) -> 63 | E5: =SUMPRODUCT(--ISNUMBER(SEARCH($A5,coding!$I$2:$I$146))) -> 0 | F5: =SUMPRODUCT(--ISNUMBER(SEARCH($A5,coding!$J$2:$J$146))) -> 0 | G5: =SUMPRODUCT(--ISNUMBER(SEARCH($A5,coding!$K$2:$K$146))) -> 0
A6: T3 | B6: =IFERROR(INDEX(codebook!$C:$C,MATCH($A6,codebook!$B:$B,0)),"") -> Hallucinated literary attribution | C6: =SUMPRODUCT(--ISNUMBER(SEARCH($A6,coding!$H$2:$H$146))) -> 12 | D6: =SUMPRODUCT(--ISNUMBER(SEARCH($A6,coding!$O$2:$O$146))) -> 13 | E6: =SUMPRODUCT(--ISNUMBER(SEARCH($A6,coding!$I$2:$I$146))) -> 0 | F6: =SUMPRODUCT(--ISNUMBER(SEARCH($A6,coding!$J$2:$J$146))) -> 0 | G6: =SUMPRODUCT(--ISNUMBER(SEARCH($A6,coding!$K$2:$K$146))) -> 0
A7: T4 | B7: =IFERROR(INDEX(codebook!$C:$C,MATCH($A7,codebook!$B:$B,0)),"") -> Fabricated / missing references | C7: =SUMPRODUCT(--ISNUMBER(SEARCH($A7,coding!$H$2:$H$146))) -> 20 | D7: =SUMPRODUCT(--ISNUMBER(SEARCH($A7,coding!$O$2:$O$146))) -> 23 | E7: =SUMPRODUCT(--ISNUMBER(SEARCH($A7,coding!$I$2:$I$146))) -> 0 | F7: =SUMPRODUCT(--ISNUMBER(SEARCH($A7,coding!$J$2:$J$146))) -> 0 | G7: =SUMPRODUCT(--ISNUMBER(SEARCH($A7,coding!$K$2:$K$146))) -> 0
